2013-04-06 00:21:30+0000 [-] Log opened.
2013-04-06 00:21:30+0000 [-] twistd 13.0.0 (/usr/bin/python 2.7.3) starting up.
2013-04-06 00:21:30+0000 [-] reactor class: twisted.internet.epollreactor.EPollReactor.
2013-04-06 00:21:30+0000 [-] ServerFactory starting on 4000
2013-04-06 00:21:30+0000 [-] Starting factory <twisted.internet.protocol.ServerFactory instance at 0x2c6e368>
2013-04-06 00:21:30+0000 [-] Site starting on 8000
2013-04-06 00:21:30+0000 [-] Starting factory <twisted.web.server.Site instance at 0x2c17f38>
2013-04-06 00:21:30+0000 [-] Starting factory <src.server.amp.AmpClientFactory instance at 0x2b08c20>
2013-04-06 00:21:30+0000 [Uninitialized] <twisted.internet.tcp.Connector instance at 0x2cfb128> will retry in 1 seconds
2013-04-06 00:21:30+0000 [Uninitialized] Stopping factory <src.server.amp.AmpClientFactory instance at 0x2b08c20>
2013-04-06 00:21:31+0000 [-] Starting factory <src.server.amp.AmpClientFactory instance at 0x2b08c20>
2013-04-06 00:21:31+0000 [Uninitialized] AMPProtocol connection established (HOST:IPv4Address(TCP, '127.0.0.1', 45822) PEER:IPv4Address(TCP, '127.0.0.1', 5000))
2013-04-06 00:21:54+0000 [HTTPChannelWithXForwardedFor,0,174.52.125.106] /usr/lib/python2.7/site-packages/Django-1.5.1-py2.7.egg/django/conf/urls/defaults.py:3: exceptions.DeprecationWarning: django.conf.urls.defaults is deprecated; use django.conf.urls instead
2013-04-06 01:01:01+0000 [HTTPChannelWithXForwardedFor,98,75.165.206.236] [::] Traceback (most recent call last):
2013-04-06 01:01:01+0000 [HTTPChannelWithXForwardedFor,98,75.165.206.236] [::]   File "/home/YourCyborg/evennia/src/players/manager.py", line 35, in func
2013-04-06 01:01:01+0000 [HTTPChannelWithXForwardedFor,98,75.165.206.236] [::]     players.append(user.get_profile())
2013-04-06 01:01:01+0000 [HTTPChannelWithXForwardedFor,98,75.165.206.236] [::]   File "/usr/lib/python2.7/site-packages/Django-1.5.1-py2.7.egg/django/contrib/auth/models.py", line 450, in get_profile
2013-04-06 01:01:01+0000 [HTTPChannelWithXForwardedFor,98,75.165.206.236] [::]     self._state.db).get(user__id__exact=self.id)
2013-04-06 01:01:01+0000 [HTTPChannelWithXForwardedFor,98,75.165.206.236] [::]   File "/home/YourCyborg/evennia/src/utils/idmapper/manager.py", line 39, in get
2013-04-06 01:01:01+0000 [HTTPChannelWithXForwardedFor,98,75.165.206.236] [::]     inst = super(SharedMemoryManager, self).get(**kwargs)
2013-04-06 01:01:01+0000 [HTTPChannelWithXForwardedFor,98,75.165.206.236] [::]   File "/usr/lib/python2.7/site-packages/Django-1.5.1-py2.7.egg/django/db/models/manager.py", line 143, in get
2013-04-06 01:01:01+0000 [HTTPChannelWithXForwardedFor,98,75.165.206.236] [::]     return self.get_query_set().get(*args, **kwargs)
2013-04-06 01:01:01+0000 [HTTPChannelWithXForwardedFor,98,75.165.206.236] [::]   File "/usr/lib/python2.7/site-packages/Django-1.5.1-py2.7.egg/django/db/models/query.py", line 389, in get
2013-04-06 01:01:01+0000 [HTTPChannelWithXForwardedFor,98,75.165.206.236] [::]     (self.model._meta.object_name, kwargs))
2013-04-06 01:01:01+0000 [HTTPChannelWithXForwardedFor,98,75.165.206.236] [::] DoesNotExist: PlayerDB matching query does not exist. Lookup parameters were {'user__id__exact': 1}
2013-04-06 01:01:01+0000 [HTTPChannelWithXForwardedFor,98,75.165.206.236] [EE] No connection User<->Player, maybe database was partially reset?
2013-04-06 01:01:01+0000 [HTTPChannelWithXForwardedFor,98,75.165.206.236] [::] Traceback (most recent call last):
2013-04-06 01:01:01+0000 [HTTPChannelWithXForwardedFor,98,75.165.206.236] [::]   File "/home/YourCyborg/evennia/src/players/manager.py", line 35, in func
2013-04-06 01:01:01+0000 [HTTPChannelWithXForwardedFor,98,75.165.206.236] [::]     players.append(user.get_profile())
2013-04-06 01:01:01+0000 [HTTPChannelWithXForwardedFor,98,75.165.206.236] [::]   File "/usr/lib/python2.7/site-packages/Django-1.5.1-py2.7.egg/django/contrib/auth/models.py", line 450, in get_profile
2013-04-06 01:01:01+0000 [HTTPChannelWithXForwardedFor,98,75.165.206.236] [::]     self._state.db).get(user__id__exact=self.id)
2013-04-06 01:01:01+0000 [HTTPChannelWithXForwardedFor,98,75.165.206.236] [::]   File "/home/YourCyborg/evennia/src/utils/idmapper/manager.py", line 39, in get
2013-04-06 01:01:01+0000 [HTTPChannelWithXForwardedFor,98,75.165.206.236] [::]     inst = super(SharedMemoryManager, self).get(**kwargs)
2013-04-06 01:01:01+0000 [HTTPChannelWithXForwardedFor,98,75.165.206.236] [::]   File "/usr/lib/python2.7/site-packages/Django-1.5.1-py2.7.egg/django/db/models/manager.py", line 143, in get
2013-04-06 01:01:01+0000 [HTTPChannelWithXForwardedFor,98,75.165.206.236] [::]     return self.get_query_set().get(*args, **kwargs)
2013-04-06 01:01:01+0000 [HTTPChannelWithXForwardedFor,98,75.165.206.236] [::]   File "/usr/lib/python2.7/site-packages/Django-1.5.1-py2.7.egg/django/db/models/query.py", line 389, in get
2013-04-06 01:01:01+0000 [HTTPChannelWithXForwardedFor,98,75.165.206.236] [::]     (self.model._meta.object_name, kwargs))
2013-04-06 01:01:01+0000 [HTTPChannelWithXForwardedFor,98,75.165.206.236] [::] DoesNotExist: PlayerDB matching query does not exist. Lookup parameters were {'user__id__exact': 1}
2013-04-06 01:01:01+0000 [HTTPChannelWithXForwardedFor,98,75.165.206.236] [EE] No connection User<->Player, maybe database was partially reset?
2013-04-06 02:07:51+0000 [HTTPChannelWithXForwardedFor,226,174.52.125.106] [::] Traceback (most recent call last):
2013-04-06 02:07:51+0000 [HTTPChannelWithXForwardedFor,226,174.52.125.106] [::]   File "/home/YourCyborg/evennia/src/players/manager.py", line 35, in func
2013-04-06 02:07:51+0000 [HTTPChannelWithXForwardedFor,226,174.52.125.106] [::]     players.append(user.get_profile())
2013-04-06 02:07:51+0000 [HTTPChannelWithXForwardedFor,226,174.52.125.106] [::]   File "/usr/lib/python2.7/site-packages/Django-1.5.1-py2.7.egg/django/contrib/auth/models.py", line 450, in get_profile
2013-04-06 02:07:51+0000 [HTTPChannelWithXForwardedFor,226,174.52.125.106] [::]     self._state.db).get(user__id__exact=self.id)
2013-04-06 02:07:51+0000 [HTTPChannelWithXForwardedFor,226,174.52.125.106] [::]   File "/home/YourCyborg/evennia/src/utils/idmapper/manager.py", line 39, in get
2013-04-06 02:07:51+0000 [HTTPChannelWithXForwardedFor,226,174.52.125.106] [::]     inst = super(SharedMemoryManager, self).get(**kwargs)
2013-04-06 02:07:51+0000 [HTTPChannelWithXForwardedFor,226,174.52.125.106] [::]   File "/usr/lib/python2.7/site-packages/Django-1.5.1-py2.7.egg/django/db/models/manager.py", line 143, in get
2013-04-06 02:07:51+0000 [HTTPChannelWithXForwardedFor,226,174.52.125.106] [::]     return self.get_query_set().get(*args, **kwargs)
2013-04-06 02:07:51+0000 [HTTPChannelWithXForwardedFor,226,174.52.125.106] [::]   File "/usr/lib/python2.7/site-packages/Django-1.5.1-py2.7.egg/django/db/models/query.py", line 389, in get
2013-04-06 02:07:51+0000 [HTTPChannelWithXForwardedFor,226,174.52.125.106] [::]     (self.model._meta.object_name, kwargs))
2013-04-06 02:07:51+0000 [HTTPChannelWithXForwardedFor,226,174.52.125.106] [::] DoesNotExist: PlayerDB matching query does not exist. Lookup parameters were {'user__id__exact': 1}
2013-04-06 02:07:51+0000 [HTTPChannelWithXForwardedFor,226,174.52.125.106] [EE] No connection User<->Player, maybe database was partially reset?
2013-04-06 02:07:51+0000 [HTTPChannelWithXForwardedFor,226,174.52.125.106] [::] Traceback (most recent call last):
2013-04-06 02:07:51+0000 [HTTPChannelWithXForwardedFor,226,174.52.125.106] [::]   File "/home/YourCyborg/evennia/src/players/manager.py", line 35, in func
2013-04-06 02:07:51+0000 [HTTPChannelWithXForwardedFor,226,174.52.125.106] [::]     players.append(user.get_profile())
2013-04-06 02:07:51+0000 [HTTPChannelWithXForwardedFor,226,174.52.125.106] [::]   File "/usr/lib/python2.7/site-packages/Django-1.5.1-py2.7.egg/django/contrib/auth/models.py", line 450, in get_profile
2013-04-06 02:07:51+0000 [HTTPChannelWithXForwardedFor,226,174.52.125.106] [::]     self._state.db).get(user__id__exact=self.id)
2013-04-06 02:07:51+0000 [HTTPChannelWithXForwardedFor,226,174.52.125.106] [::]   File "/home/YourCyborg/evennia/src/utils/idmapper/manager.py", line 39, in get
2013-04-06 02:07:51+0000 [HTTPChannelWithXForwardedFor,226,174.52.125.106] [::]     inst = super(SharedMemoryManager, self).get(**kwargs)
2013-04-06 02:07:51+0000 [HTTPChannelWithXForwardedFor,226,174.52.125.106] [::]   File "/usr/lib/python2.7/site-packages/Django-1.5.1-py2.7.egg/django/db/models/manager.py", line 143, in get
2013-04-06 02:07:51+0000 [HTTPChannelWithXForwardedFor,226,174.52.125.106] [::]     return self.get_query_set().get(*args, **kwargs)
2013-04-06 02:07:51+0000 [HTTPChannelWithXForwardedFor,226,174.52.125.106] [::]   File "/usr/lib/python2.7/site-packages/Django-1.5.1-py2.7.egg/django/db/models/query.py", line 389, in get
2013-04-06 02:07:51+0000 [HTTPChannelWithXForwardedFor,226,174.52.125.106] [::]     (self.model._meta.object_name, kwargs))
2013-04-06 02:07:51+0000 [HTTPChannelWithXForwardedFor,226,174.52.125.106] [::] DoesNotExist: PlayerDB matching query does not exist. Lookup parameters were {'user__id__exact': 1}
2013-04-06 02:07:51+0000 [HTTPChannelWithXForwardedFor,226,174.52.125.106] [EE] No connection User<->Player, maybe database was partially reset?
2013-04-06 02:27:55+0000 [HTTPChannelWithXForwardedFor,264,174.52.125.106] [::] Traceback (most recent call last):
2013-04-06 02:27:55+0000 [HTTPChannelWithXForwardedFor,264,174.52.125.106] [::]   File "/home/YourCyborg/evennia/src/players/manager.py", line 35, in func
2013-04-06 02:27:55+0000 [HTTPChannelWithXForwardedFor,264,174.52.125.106] [::]     players.append(user.get_profile())
2013-04-06 02:27:55+0000 [HTTPChannelWithXForwardedFor,264,174.52.125.106] [::]   File "/usr/lib/python2.7/site-packages/Django-1.5.1-py2.7.egg/django/contrib/auth/models.py", line 450, in get_profile
2013-04-06 02:27:55+0000 [HTTPChannelWithXForwardedFor,264,174.52.125.106] [::]     self._state.db).get(user__id__exact=self.id)
2013-04-06 02:27:55+0000 [HTTPChannelWithXForwardedFor,264,174.52.125.106] [::]   File "/home/YourCyborg/evennia/src/utils/idmapper/manager.py", line 39, in get
2013-04-06 02:27:55+0000 [HTTPChannelWithXForwardedFor,264,174.52.125.106] [::]     inst = super(SharedMemoryManager, self).get(**kwargs)
2013-04-06 02:27:55+0000 [HTTPChannelWithXForwardedFor,264,174.52.125.106] [::]   File "/usr/lib/python2.7/site-packages/Django-1.5.1-py2.7.egg/django/db/models/manager.py", line 143, in get
2013-04-06 02:27:55+0000 [HTTPChannelWithXForwardedFor,264,174.52.125.106] [::]     return self.get_query_set().get(*args, **kwargs)
2013-04-06 02:27:55+0000 [HTTPChannelWithXForwardedFor,264,174.52.125.106] [::]   File "/usr/lib/python2.7/site-packages/Django-1.5.1-py2.7.egg/django/db/models/query.py", line 389, in get
2013-04-06 02:27:55+0000 [HTTPChannelWithXForwardedFor,264,174.52.125.106] [::]     (self.model._meta.object_name, kwargs))
2013-04-06 02:27:55+0000 [HTTPChannelWithXForwardedFor,264,174.52.125.106] [::] DoesNotExist: PlayerDB matching query does not exist. Lookup parameters were {'user__id__exact': 1}
2013-04-06 02:27:55+0000 [HTTPChannelWithXForwardedFor,264,174.52.125.106] [EE] No connection User<->Player, maybe database was partially reset?
2013-04-06 02:27:55+0000 [HTTPChannelWithXForwardedFor,264,174.52.125.106] [::] Traceback (most recent call last):
2013-04-06 02:27:55+0000 [HTTPChannelWithXForwardedFor,264,174.52.125.106] [::]   File "/home/YourCyborg/evennia/src/players/manager.py", line 35, in func
2013-04-06 02:27:55+0000 [HTTPChannelWithXForwardedFor,264,174.52.125.106] [::]     players.append(user.get_profile())
2013-04-06 02:27:55+0000 [HTTPChannelWithXForwardedFor,264,174.52.125.106] [::]   File "/usr/lib/python2.7/site-packages/Django-1.5.1-py2.7.egg/django/contrib/auth/models.py", line 450, in get_profile
2013-04-06 02:27:55+0000 [HTTPChannelWithXForwardedFor,264,174.52.125.106] [::]     self._state.db).get(user__id__exact=self.id)
2013-04-06 02:27:55+0000 [HTTPChannelWithXForwardedFor,264,174.52.125.106] [::]   File "/home/YourCyborg/evennia/src/utils/idmapper/manager.py", line 39, in get
2013-04-06 02:27:55+0000 [HTTPChannelWithXForwardedFor,264,174.52.125.106] [::]     inst = super(SharedMemoryManager, self).get(**kwargs)
2013-04-06 02:27:55+0000 [HTTPChannelWithXForwardedFor,264,174.52.125.106] [::]   File "/usr/lib/python2.7/site-packages/Django-1.5.1-py2.7.egg/django/db/models/manager.py", line 143, in get
2013-04-06 02:27:55+0000 [HTTPChannelWithXForwardedFor,264,174.52.125.106] [::]     return self.get_query_set().get(*args, **kwargs)
2013-04-06 02:27:55+0000 [HTTPChannelWithXForwardedFor,264,174.52.125.106] [::]   File "/usr/lib/python2.7/site-packages/Django-1.5.1-py2.7.egg/django/db/models/query.py", line 389, in get
2013-04-06 02:27:55+0000 [HTTPChannelWithXForwardedFor,264,174.52.125.106] [::]     (self.model._meta.object_name, kwargs))
2013-04-06 02:27:55+0000 [HTTPChannelWithXForwardedFor,264,174.52.125.106] [::] DoesNotExist: PlayerDB matching query does not exist. Lookup parameters were {'user__id__exact': 1}
2013-04-06 02:27:55+0000 [HTTPChannelWithXForwardedFor,264,174.52.125.106] [EE] No connection User<->Player, maybe database was partially reset?
2013-04-06 02:32:13+0000 [HTTPChannelWithXForwardedFor,274,174.52.125.106] [::] Traceback (most recent call last):
2013-04-06 02:32:13+0000 [HTTPChannelWithXForwardedFor,274,174.52.125.106] [::]   File "/home/YourCyborg/evennia/src/players/manager.py", line 35, in func
2013-04-06 02:32:13+0000 [HTTPChannelWithXForwardedFor,274,174.52.125.106] [::]     players.append(user.get_profile())
2013-04-06 02:32:13+0000 [HTTPChannelWithXForwardedFor,274,174.52.125.106] [::]   File "/usr/lib/python2.7/site-packages/Django-1.5.1-py2.7.egg/django/contrib/auth/models.py", line 450, in get_profile
2013-04-06 02:32:13+0000 [HTTPChannelWithXForwardedFor,274,174.52.125.106] [::]     self._state.db).get(user__id__exact=self.id)
2013-04-06 02:32:13+0000 [HTTPChannelWithXForwardedFor,274,174.52.125.106] [::]   File "/home/YourCyborg/evennia/src/utils/idmapper/manager.py", line 39, in get
2013-04-06 02:32:13+0000 [HTTPChannelWithXForwardedFor,274,174.52.125.106] [::]     inst = super(SharedMemoryManager, self).get(**kwargs)
2013-04-06 02:32:13+0000 [HTTPChannelWithXForwardedFor,274,174.52.125.106] [::]   File "/usr/lib/python2.7/site-packages/Django-1.5.1-py2.7.egg/django/db/models/manager.py", line 143, in get
2013-04-06 02:32:13+0000 [HTTPChannelWithXForwardedFor,274,174.52.125.106] [::]     return self.get_query_set().get(*args, **kwargs)
2013-04-06 02:32:13+0000 [HTTPChannelWithXForwardedFor,274,174.52.125.106] [::]   File "/usr/lib/python2.7/site-packages/Django-1.5.1-py2.7.egg/django/db/models/query.py", line 389, in get
2013-04-06 02:32:13+0000 [HTTPChannelWithXForwardedFor,274,174.52.125.106] [::]     (self.model._meta.object_name, kwargs))
2013-04-06 02:32:13+0000 [HTTPChannelWithXForwardedFor,274,174.52.125.106] [::] DoesNotExist: PlayerDB matching query does not exist. Lookup parameters were {'user__id__exact': 1}
2013-04-06 02:32:13+0000 [HTTPChannelWithXForwardedFor,274,174.52.125.106] [EE] No connection User<->Player, maybe database was partially reset?
2013-04-06 02:32:13+0000 [HTTPChannelWithXForwardedFor,274,174.52.125.106] [::] Traceback (most recent call last):
2013-04-06 02:32:13+0000 [HTTPChannelWithXForwardedFor,274,174.52.125.106] [::]   File "/home/YourCyborg/evennia/src/players/manager.py", line 35, in func
2013-04-06 02:32:13+0000 [HTTPChannelWithXForwardedFor,274,174.52.125.106] [::]     players.append(user.get_profile())
2013-04-06 02:32:13+0000 [HTTPChannelWithXForwardedFor,274,174.52.125.106] [::]   File "/usr/lib/python2.7/site-packages/Django-1.5.1-py2.7.egg/django/contrib/auth/models.py", line 450, in get_profile
2013-04-06 02:32:13+0000 [HTTPChannelWithXForwardedFor,274,174.52.125.106] [::]     self._state.db).get(user__id__exact=self.id)
2013-04-06 02:32:13+0000 [HTTPChannelWithXForwardedFor,274,174.52.125.106] [::]   File "/home/YourCyborg/evennia/src/utils/idmapper/manager.py", line 39, in get
2013-04-06 02:32:13+0000 [HTTPChannelWithXForwardedFor,274,174.52.125.106] [::]     inst = super(SharedMemoryManager, self).get(**kwargs)
2013-04-06 02:32:13+0000 [HTTPChannelWithXForwardedFor,274,174.52.125.106] [::]   File "/usr/lib/python2.7/site-packages/Django-1.5.1-py2.7.egg/django/db/models/manager.py", line 143, in get
2013-04-06 02:32:13+0000 [HTTPChannelWithXForwardedFor,274,174.52.125.106] [::]     return self.get_query_set().get(*args, **kwargs)
2013-04-06 02:32:13+0000 [HTTPChannelWithXForwardedFor,274,174.52.125.106] [::]   File "/usr/lib/python2.7/site-packages/Django-1.5.1-py2.7.egg/django/db/models/query.py", line 389, in get
2013-04-06 02:32:13+0000 [HTTPChannelWithXForwardedFor,274,174.52.125.106] [::]     (self.model._meta.object_name, kwargs))
2013-04-06 02:32:13+0000 [HTTPChannelWithXForwardedFor,274,174.52.125.106] [::] DoesNotExist: PlayerDB matching query does not exist. Lookup parameters were {'user__id__exact': 1}
2013-04-06 02:32:13+0000 [HTTPChannelWithXForwardedFor,274,174.52.125.106] [EE] No connection User<->Player, maybe database was partially reset?
2013-04-06 02:32:32+0000 [HTTPChannelWithXForwardedFor,274,174.52.125.106] [::] Traceback (most recent call last):
2013-04-06 02:32:32+0000 [HTTPChannelWithXForwardedFor,274,174.52.125.106] [::]   File "/home/YourCyborg/evennia/src/players/manager.py", line 35, in func
2013-04-06 02:32:32+0000 [HTTPChannelWithXForwardedFor,274,174.52.125.106] [::]     players.append(user.get_profile())
2013-04-06 02:32:32+0000 [HTTPChannelWithXForwardedFor,274,174.52.125.106] [::]   File "/usr/lib/python2.7/site-packages/Django-1.5.1-py2.7.egg/django/contrib/auth/models.py", line 450, in get_profile
2013-04-06 02:32:32+0000 [HTTPChannelWithXForwardedFor,274,174.52.125.106] [::]     self._state.db).get(user__id__exact=self.id)
2013-04-06 02:32:32+0000 [HTTPChannelWithXForwardedFor,274,174.52.125.106] [::]   File "/home/YourCyborg/evennia/src/utils/idmapper/manager.py", line 39, in get
2013-04-06 02:32:32+0000 [HTTPChannelWithXForwardedFor,274,174.52.125.106] [::]     inst = super(SharedMemoryManager, self).get(**kwargs)
2013-04-06 02:32:32+0000 [HTTPChannelWithXForwardedFor,274,174.52.125.106] [::]   File "/usr/lib/python2.7/site-packages/Django-1.5.1-py2.7.egg/django/db/models/manager.py", line 143, in get
2013-04-06 02:32:32+0000 [HTTPChannelWithXForwardedFor,274,174.52.125.106] [::]     return self.get_query_set().get(*args, **kwargs)
2013-04-06 02:32:32+0000 [HTTPChannelWithXForwardedFor,274,174.52.125.106] [::]   File "/usr/lib/python2.7/site-packages/Django-1.5.1-py2.7.egg/django/db/models/query.py", line 389, in get
2013-04-06 02:32:32+0000 [HTTPChannelWithXForwardedFor,274,174.52.125.106] [::]     (self.model._meta.object_name, kwargs))
2013-04-06 02:32:32+0000 [HTTPChannelWithXForwardedFor,274,174.52.125.106] [::] DoesNotExist: PlayerDB matching query does not exist. Lookup parameters were {'user__id__exact': 1}
2013-04-06 02:32:32+0000 [HTTPChannelWithXForwardedFor,274,174.52.125.106] [EE] No connection User<->Player, maybe database was partially reset?
2013-04-06 02:32:32+0000 [HTTPChannelWithXForwardedFor,274,174.52.125.106] [::] Traceback (most recent call last):
2013-04-06 02:32:32+0000 [HTTPChannelWithXForwardedFor,274,174.52.125.106] [::]   File "/home/YourCyborg/evennia/src/players/manager.py", line 35, in func
2013-04-06 02:32:32+0000 [HTTPChannelWithXForwardedFor,274,174.52.125.106] [::]     players.append(user.get_profile())
2013-04-06 02:32:32+0000 [HTTPChannelWithXForwardedFor,274,174.52.125.106] [::]   File "/usr/lib/python2.7/site-packages/Django-1.5.1-py2.7.egg/django/contrib/auth/models.py", line 450, in get_profile
2013-04-06 02:32:32+0000 [HTTPChannelWithXForwardedFor,274,174.52.125.106] [::]     self._state.db).get(user__id__exact=self.id)
2013-04-06 02:32:32+0000 [HTTPChannelWithXForwardedFor,274,174.52.125.106] [::]   File "/home/YourCyborg/evennia/src/utils/idmapper/manager.py", line 39, in get
2013-04-06 02:32:32+0000 [HTTPChannelWithXForwardedFor,274,174.52.125.106] [::]     inst = super(SharedMemoryManager, self).get(**kwargs)
2013-04-06 02:32:32+0000 [HTTPChannelWithXForwardedFor,274,174.52.125.106] [::]   File "/usr/lib/python2.7/site-packages/Django-1.5.1-py2.7.egg/django/db/models/manager.py", line 143, in get
2013-04-06 02:32:32+0000 [HTTPChannelWithXForwardedFor,274,174.52.125.106] [::]     return self.get_query_set().get(*args, **kwargs)
2013-04-06 02:32:32+0000 [HTTPChannelWithXForwardedFor,274,174.52.125.106] [::]   File "/usr/lib/python2.7/site-packages/Django-1.5.1-py2.7.egg/django/db/models/query.py", line 389, in get
2013-04-06 02:32:32+0000 [HTTPChannelWithXForwardedFor,274,174.52.125.106] [::]     (self.model._meta.object_name, kwargs))
2013-04-06 02:32:32+0000 [HTTPChannelWithXForwardedFor,274,174.52.125.106] [::] DoesNotExist: PlayerDB matching query does not exist. Lookup parameters were {'user__id__exact': 1}
2013-04-06 02:32:32+0000 [HTTPChannelWithXForwardedFor,274,174.52.125.106] [EE] No connection User<->Player, maybe database was partially reset?
2013-04-06 02:40:32+0000 [HTTPChannelWithXForwardedFor,291,174.52.125.106] /usr/lib/python2.7/site-packages/Django-1.5.1-py2.7.egg/django/core/management/__init__.py:409: exceptions.DeprecationWarning: The 'setup_environ' function is deprecated, you likely need to update your 'manage.py'; please see the Django 1.4 release notes (https://docs.djangoproject.com/en/dev/releases/1.4/).
2013-04-06 02:53:06+0000 [HTTPChannelWithXForwardedFor,318,174.52.125.106] [::] Traceback (most recent call last):
2013-04-06 02:53:06+0000 [HTTPChannelWithXForwardedFor,318,174.52.125.106] [::]   File "/home/YourCyborg/evennia/src/players/manager.py", line 35, in func
2013-04-06 02:53:06+0000 [HTTPChannelWithXForwardedFor,318,174.52.125.106] [::]     players.append(user.get_profile())
2013-04-06 02:53:06+0000 [HTTPChannelWithXForwardedFor,318,174.52.125.106] [::]   File "/usr/lib/python2.7/site-packages/Django-1.5.1-py2.7.egg/django/contrib/auth/models.py", line 450, in get_profile
2013-04-06 02:53:06+0000 [HTTPChannelWithXForwardedFor,318,174.52.125.106] [::]     self._state.db).get(user__id__exact=self.id)
2013-04-06 02:53:06+0000 [HTTPChannelWithXForwardedFor,318,174.52.125.106] [::]   File "/home/YourCyborg/evennia/src/utils/idmapper/manager.py", line 39, in get
2013-04-06 02:53:06+0000 [HTTPChannelWithXForwardedFor,318,174.52.125.106] [::]     inst = super(SharedMemoryManager, self).get(**kwargs)
2013-04-06 02:53:06+0000 [HTTPChannelWithXForwardedFor,318,174.52.125.106] [::]   File "/usr/lib/python2.7/site-packages/Django-1.5.1-py2.7.egg/django/db/models/manager.py", line 143, in get
2013-04-06 02:53:06+0000 [HTTPChannelWithXForwardedFor,318,174.52.125.106] [::]     return self.get_query_set().get(*args, **kwargs)
2013-04-06 02:53:06+0000 [HTTPChannelWithXForwardedFor,318,174.52.125.106] [::]   File "/usr/lib/python2.7/site-packages/Django-1.5.1-py2.7.egg/django/db/models/query.py", line 389, in get
2013-04-06 02:53:06+0000 [HTTPChannelWithXForwardedFor,318,174.52.125.106] [::]     (self.model._meta.object_name, kwargs))
2013-04-06 02:53:06+0000 [HTTPChannelWithXForwardedFor,318,174.52.125.106] [::] DoesNotExist: PlayerDB matching query does not exist. Lookup parameters were {'user__id__exact': 1}
2013-04-06 02:53:06+0000 [HTTPChannelWithXForwardedFor,318,174.52.125.106] [EE] No connection User<->Player, maybe database was partially reset?
2013-04-06 02:53:06+0000 [HTTPChannelWithXForwardedFor,318,174.52.125.106] [::] Traceback (most recent call last):
2013-04-06 02:53:06+0000 [HTTPChannelWithXForwardedFor,318,174.52.125.106] [::]   File "/home/YourCyborg/evennia/src/players/manager.py", line 35, in func
2013-04-06 02:53:06+0000 [HTTPChannelWithXForwardedFor,318,174.52.125.106] [::]     players.append(user.get_profile())
2013-04-06 02:53:06+0000 [HTTPChannelWithXForwardedFor,318,174.52.125.106] [::]   File "/usr/lib/python2.7/site-packages/Django-1.5.1-py2.7.egg/django/contrib/auth/models.py", line 450, in get_profile
2013-04-06 02:53:06+0000 [HTTPChannelWithXForwardedFor,318,174.52.125.106] [::]     self._state.db).get(user__id__exact=self.id)
2013-04-06 02:53:06+0000 [HTTPChannelWithXForwardedFor,318,174.52.125.106] [::]   File "/home/YourCyborg/evennia/src/utils/idmapper/manager.py", line 39, in get
2013-04-06 02:53:06+0000 [HTTPChannelWithXForwardedFor,318,174.52.125.106] [::]     inst = super(SharedMemoryManager, self).get(**kwargs)
2013-04-06 02:53:06+0000 [HTTPChannelWithXForwardedFor,318,174.52.125.106] [::]   File "/usr/lib/python2.7/site-packages/Django-1.5.1-py2.7.egg/django/db/models/manager.py", line 143, in get
2013-04-06 02:53:06+0000 [HTTPChannelWithXForwardedFor,318,174.52.125.106] [::]     return self.get_query_set().get(*args, **kwargs)
2013-04-06 02:53:06+0000 [HTTPChannelWithXForwardedFor,318,174.52.125.106] [::]   File "/usr/lib/python2.7/site-packages/Django-1.5.1-py2.7.egg/django/db/models/query.py", line 389, in get
2013-04-06 02:53:06+0000 [HTTPChannelWithXForwardedFor,318,174.52.125.106] [::]     (self.model._meta.object_name, kwargs))
2013-04-06 02:53:06+0000 [HTTPChannelWithXForwardedFor,318,174.52.125.106] [::] DoesNotExist: PlayerDB matching query does not exist. Lookup parameters were {'user__id__exact': 1}
2013-04-06 02:53:06+0000 [HTTPChannelWithXForwardedFor,318,174.52.125.106] [EE] No connection User<->Player, maybe database was partially reset?
2013-04-06 03:47:12+0000 [HTTPChannelWithXForwardedFor,396,174.52.125.106] [::] Traceback (most recent call last):
2013-04-06 03:47:12+0000 [HTTPChannelWithXForwardedFor,396,174.52.125.106] [::]   File "/home/YourCyborg/evennia/src/players/manager.py", line 35, in func
2013-04-06 03:47:12+0000 [HTTPChannelWithXForwardedFor,396,174.52.125.106] [::]     players.append(user.get_profile())
2013-04-06 03:47:12+0000 [HTTPChannelWithXForwardedFor,396,174.52.125.106] [::]   File "/usr/lib/python2.7/site-packages/Django-1.5.1-py2.7.egg/django/contrib/auth/models.py", line 450, in get_profile
2013-04-06 03:47:12+0000 [HTTPChannelWithXForwardedFor,396,174.52.125.106] [::]     self._state.db).get(user__id__exact=self.id)
2013-04-06 03:47:12+0000 [HTTPChannelWithXForwardedFor,396,174.52.125.106] [::]   File "/home/YourCyborg/evennia/src/utils/idmapper/manager.py", line 39, in get
2013-04-06 03:47:12+0000 [HTTPChannelWithXForwardedFor,396,174.52.125.106] [::]     inst = super(SharedMemoryManager, self).get(**kwargs)
2013-04-06 03:47:12+0000 [HTTPChannelWithXForwardedFor,396,174.52.125.106] [::]   File "/usr/lib/python2.7/site-packages/Django-1.5.1-py2.7.egg/django/db/models/manager.py", line 143, in get
2013-04-06 03:47:12+0000 [HTTPChannelWithXForwardedFor,396,174.52.125.106] [::]     return self.get_query_set().get(*args, **kwargs)
2013-04-06 03:47:12+0000 [HTTPChannelWithXForwardedFor,396,174.52.125.106] [::]   File "/usr/lib/python2.7/site-packages/Django-1.5.1-py2.7.egg/django/db/models/query.py", line 389, in get
2013-04-06 03:47:12+0000 [HTTPChannelWithXForwardedFor,396,174.52.125.106] [::]     (self.model._meta.object_name, kwargs))
2013-04-06 03:47:12+0000 [HTTPChannelWithXForwardedFor,396,174.52.125.106] [::] DoesNotExist: PlayerDB matching query does not exist. Lookup parameters were {'user__id__exact': 1}
2013-04-06 03:47:12+0000 [HTTPChannelWithXForwardedFor,396,174.52.125.106] [EE] No connection User<->Player, maybe database was partially reset?
2013-04-06 03:47:12+0000 [HTTPChannelWithXForwardedFor,396,174.52.125.106] [::] Traceback (most recent call last):
2013-04-06 03:47:12+0000 [HTTPChannelWithXForwardedFor,396,174.52.125.106] [::]   File "/home/YourCyborg/evennia/src/players/manager.py", line 35, in func
2013-04-06 03:47:12+0000 [HTTPChannelWithXForwardedFor,396,174.52.125.106] [::]     players.append(user.get_profile())
2013-04-06 03:47:12+0000 [HTTPChannelWithXForwardedFor,396,174.52.125.106] [::]   File "/usr/lib/python2.7/site-packages/Django-1.5.1-py2.7.egg/django/contrib/auth/models.py", line 450, in get_profile
2013-04-06 03:47:12+0000 [HTTPChannelWithXForwardedFor,396,174.52.125.106] [::]     self._state.db).get(user__id__exact=self.id)
2013-04-06 03:47:12+0000 [HTTPChannelWithXForwardedFor,396,174.52.125.106] [::]   File "/home/YourCyborg/evennia/src/utils/idmapper/manager.py", line 39, in get
2013-04-06 03:47:12+0000 [HTTPChannelWithXForwardedFor,396,174.52.125.106] [::]     inst = super(SharedMemoryManager, self).get(**kwargs)
2013-04-06 03:47:12+0000 [HTTPChannelWithXForwardedFor,396,174.52.125.106] [::]   File "/usr/lib/python2.7/site-packages/Django-1.5.1-py2.7.egg/django/db/models/manager.py", line 143, in get
2013-04-06 03:47:12+0000 [HTTPChannelWithXForwardedFor,396,174.52.125.106] [::]     return self.get_query_set().get(*args, **kwargs)
2013-04-06 03:47:12+0000 [HTTPChannelWithXForwardedFor,396,174.52.125.106] [::]   File "/usr/lib/python2.7/site-packages/Django-1.5.1-py2.7.egg/django/db/models/query.py", line 389, in get
2013-04-06 03:47:12+0000 [HTTPChannelWithXForwardedFor,396,174.52.125.106] [::]     (self.model._meta.object_name, kwargs))
2013-04-06 03:47:12+0000 [HTTPChannelWithXForwardedFor,396,174.52.125.106] [::] DoesNotExist: PlayerDB matching query does not exist. Lookup parameters were {'user__id__exact': 1}
2013-04-06 03:47:12+0000 [HTTPChannelWithXForwardedFor,396,174.52.125.106] [EE] No connection User<->Player, maybe database was partially reset?
2013-04-06 15:38:27+0000 [HTTPChannelWithXForwardedFor,400,174.52.125.106] [::] Traceback (most recent call last):
2013-04-06 15:38:27+0000 [HTTPChannelWithXForwardedFor,400,174.52.125.106] [::]   File "/home/YourCyborg/evennia/src/players/manager.py", line 35, in func
2013-04-06 15:38:27+0000 [HTTPChannelWithXForwardedFor,400,174.52.125.106] [::]     players.append(user.get_profile())
2013-04-06 15:38:27+0000 [HTTPChannelWithXForwardedFor,400,174.52.125.106] [::]   File "/usr/lib/python2.7/site-packages/Django-1.5.1-py2.7.egg/django/contrib/auth/models.py", line 450, in get_profile
2013-04-06 15:38:27+0000 [HTTPChannelWithXForwardedFor,400,174.52.125.106] [::]     self._state.db).get(user__id__exact=self.id)
2013-04-06 15:38:27+0000 [HTTPChannelWithXForwardedFor,400,174.52.125.106] [::]   File "/home/YourCyborg/evennia/src/utils/idmapper/manager.py", line 39, in get
2013-04-06 15:38:27+0000 [HTTPChannelWithXForwardedFor,400,174.52.125.106] [::]     inst = super(SharedMemoryManager, self).get(**kwargs)
2013-04-06 15:38:27+0000 [HTTPChannelWithXForwardedFor,400,174.52.125.106] [::]   File "/usr/lib/python2.7/site-packages/Django-1.5.1-py2.7.egg/django/db/models/manager.py", line 143, in get
2013-04-06 15:38:27+0000 [HTTPChannelWithXForwardedFor,400,174.52.125.106] [::]     return self.get_query_set().get(*args, **kwargs)
2013-04-06 15:38:27+0000 [HTTPChannelWithXForwardedFor,400,174.52.125.106] [::]   File "/usr/lib/python2.7/site-packages/Django-1.5.1-py2.7.egg/django/db/models/query.py", line 389, in get
2013-04-06 15:38:27+0000 [HTTPChannelWithXForwardedFor,400,174.52.125.106] [::]     (self.model._meta.object_name, kwargs))
2013-04-06 15:38:27+0000 [HTTPChannelWithXForwardedFor,400,174.52.125.106] [::] DoesNotExist: PlayerDB matching query does not exist. Lookup parameters were {'user__id__exact': 1}
2013-04-06 15:38:27+0000 [HTTPChannelWithXForwardedFor,400,174.52.125.106] [EE] No connection User<->Player, maybe database was partially reset?
2013-04-06 15:38:27+0000 [HTTPChannelWithXForwardedFor,400,174.52.125.106] [::] Traceback (most recent call last):
2013-04-06 15:38:27+0000 [HTTPChannelWithXForwardedFor,400,174.52.125.106] [::]   File "/home/YourCyborg/evennia/src/players/manager.py", line 35, in func
2013-04-06 15:38:27+0000 [HTTPChannelWithXForwardedFor,400,174.52.125.106] [::]     players.append(user.get_profile())
2013-04-06 15:38:27+0000 [HTTPChannelWithXForwardedFor,400,174.52.125.106] [::]   File "/usr/lib/python2.7/site-packages/Django-1.5.1-py2.7.egg/django/contrib/auth/models.py", line 450, in get_profile
2013-04-06 15:38:27+0000 [HTTPChannelWithXForwardedFor,400,174.52.125.106] [::]     self._state.db).get(user__id__exact=self.id)
2013-04-06 15:38:27+0000 [HTTPChannelWithXForwardedFor,400,174.52.125.106] [::]   File "/home/YourCyborg/evennia/src/utils/idmapper/manager.py", line 39, in get
2013-04-06 15:38:27+0000 [HTTPChannelWithXForwardedFor,400,174.52.125.106] [::]     inst = super(SharedMemoryManager, self).get(**kwargs)
2013-04-06 15:38:27+0000 [HTTPChannelWithXForwardedFor,400,174.52.125.106] [::]   File "/usr/lib/python2.7/site-packages/Django-1.5.1-py2.7.egg/django/db/models/manager.py", line 143, in get
2013-04-06 15:38:27+0000 [HTTPChannelWithXForwardedFor,400,174.52.125.106] [::]     return self.get_query_set().get(*args, **kwargs)
2013-04-06 15:38:27+0000 [HTTPChannelWithXForwardedFor,400,174.52.125.106] [::]   File "/usr/lib/python2.7/site-packages/Django-1.5.1-py2.7.egg/django/db/models/query.py", line 389, in get
2013-04-06 15:38:27+0000 [HTTPChannelWithXForwardedFor,400,174.52.125.106] [::]     (self.model._meta.object_name, kwargs))
2013-04-06 15:38:27+0000 [HTTPChannelWithXForwardedFor,400,174.52.125.106] [::] DoesNotExist: PlayerDB matching query does not exist. Lookup parameters were {'user__id__exact': 1}
2013-04-06 15:38:27+0000 [HTTPChannelWithXForwardedFor,400,174.52.125.106] [EE] No connection User<->Player, maybe database was partially reset?
2013-04-06 16:09:47+0000 [HTTPChannelWithXForwardedFor,404,174.52.125.106] [::] Traceback (most recent call last):
2013-04-06 16:09:47+0000 [HTTPChannelWithXForwardedFor,404,174.52.125.106] [::]   File "/home/YourCyborg/evennia/src/players/manager.py", line 35, in func
2013-04-06 16:09:47+0000 [HTTPChannelWithXForwardedFor,404,174.52.125.106] [::]     players.append(user.get_profile())
2013-04-06 16:09:47+0000 [HTTPChannelWithXForwardedFor,404,174.52.125.106] [::]   File "/usr/lib/python2.7/site-packages/Django-1.5.1-py2.7.egg/django/contrib/auth/models.py", line 450, in get_profile
2013-04-06 16:09:47+0000 [HTTPChannelWithXForwardedFor,404,174.52.125.106] [::]     self._state.db).get(user__id__exact=self.id)
2013-04-06 16:09:47+0000 [HTTPChannelWithXForwardedFor,404,174.52.125.106] [::]   File "/home/YourCyborg/evennia/src/utils/idmapper/manager.py", line 39, in get
2013-04-06 16:09:47+0000 [HTTPChannelWithXForwardedFor,404,174.52.125.106] [::]     inst = super(SharedMemoryManager, self).get(**kwargs)
2013-04-06 16:09:47+0000 [HTTPChannelWithXForwardedFor,404,174.52.125.106] [::]   File "/usr/lib/python2.7/site-packages/Django-1.5.1-py2.7.egg/django/db/models/manager.py", line 143, in get
2013-04-06 16:09:47+0000 [HTTPChannelWithXForwardedFor,404,174.52.125.106] [::]     return self.get_query_set().get(*args, **kwargs)
2013-04-06 16:09:47+0000 [HTTPChannelWithXForwardedFor,404,174.52.125.106] [::]   File "/usr/lib/python2.7/site-packages/Django-1.5.1-py2.7.egg/django/db/models/query.py", line 389, in get
2013-04-06 16:09:47+0000 [HTTPChannelWithXForwardedFor,404,174.52.125.106] [::]     (self.model._meta.object_name, kwargs))
2013-04-06 16:09:47+0000 [HTTPChannelWithXForwardedFor,404,174.52.125.106] [::] DoesNotExist: PlayerDB matching query does not exist. Lookup parameters were {'user__id__exact': 1}
2013-04-06 16:09:47+0000 [HTTPChannelWithXForwardedFor,404,174.52.125.106] [EE] No connection User<->Player, maybe database was partially reset?
2013-04-06 16:09:47+0000 [HTTPChannelWithXForwardedFor,404,174.52.125.106] [::] Traceback (most recent call last):
2013-04-06 16:09:47+0000 [HTTPChannelWithXForwardedFor,404,174.52.125.106] [::]   File "/home/YourCyborg/evennia/src/players/manager.py", line 35, in func
2013-04-06 16:09:47+0000 [HTTPChannelWithXForwardedFor,404,174.52.125.106] [::]     players.append(user.get_profile())
2013-04-06 16:09:47+0000 [HTTPChannelWithXForwardedFor,404,174.52.125.106] [::]   File "/usr/lib/python2.7/site-packages/Django-1.5.1-py2.7.egg/django/contrib/auth/models.py", line 450, in get_profile
2013-04-06 16:09:47+0000 [HTTPChannelWithXForwardedFor,404,174.52.125.106] [::]     self._state.db).get(user__id__exact=self.id)
2013-04-06 16:09:47+0000 [HTTPChannelWithXForwardedFor,404,174.52.125.106] [::]   File "/home/YourCyborg/evennia/src/utils/idmapper/manager.py", line 39, in get
2013-04-06 16:09:47+0000 [HTTPChannelWithXForwardedFor,404,174.52.125.106] [::]     inst = super(SharedMemoryManager, self).get(**kwargs)
2013-04-06 16:09:47+0000 [HTTPChannelWithXForwardedFor,404,174.52.125.106] [::]   File "/usr/lib/python2.7/site-packages/Django-1.5.1-py2.7.egg/django/db/models/manager.py", line 143, in get
2013-04-06 16:09:47+0000 [HTTPChannelWithXForwardedFor,404,174.52.125.106] [::]     return self.get_query_set().get(*args, **kwargs)
2013-04-06 16:09:47+0000 [HTTPChannelWithXForwardedFor,404,174.52.125.106] [::]   File "/usr/lib/python2.7/site-packages/Django-1.5.1-py2.7.egg/django/db/models/query.py", line 389, in get
2013-04-06 16:09:47+0000 [HTTPChannelWithXForwardedFor,404,174.52.125.106] [::]     (self.model._meta.object_name, kwargs))
2013-04-06 16:09:47+0000 [HTTPChannelWithXForwardedFor,404,174.52.125.106] [::] DoesNotExist: PlayerDB matching query does not exist. Lookup parameters were {'user__id__exact': 1}
2013-04-06 16:09:47+0000 [HTTPChannelWithXForwardedFor,404,174.52.125.106] [EE] No connection User<->Player, maybe database was partially reset?
2013-04-06 19:53:06+0000 [HTTPChannelWithXForwardedFor,408,174.52.125.106] [::] Traceback (most recent call last):
2013-04-06 19:53:06+0000 [HTTPChannelWithXForwardedFor,408,174.52.125.106] [::]   File "/home/YourCyborg/evennia/src/players/manager.py", line 35, in func
2013-04-06 19:53:06+0000 [HTTPChannelWithXForwardedFor,408,174.52.125.106] [::]     players.append(user.get_profile())
2013-04-06 19:53:06+0000 [HTTPChannelWithXForwardedFor,408,174.52.125.106] [::]   File "/usr/lib/python2.7/site-packages/Django-1.5.1-py2.7.egg/django/contrib/auth/models.py", line 450, in get_profile
2013-04-06 19:53:06+0000 [HTTPChannelWithXForwardedFor,408,174.52.125.106] [::]     self._state.db).get(user__id__exact=self.id)
2013-04-06 19:53:06+0000 [HTTPChannelWithXForwardedFor,408,174.52.125.106] [::]   File "/home/YourCyborg/evennia/src/utils/idmapper/manager.py", line 39, in get
2013-04-06 19:53:06+0000 [HTTPChannelWithXForwardedFor,408,174.52.125.106] [::]     inst = super(SharedMemoryManager, self).get(**kwargs)
2013-04-06 19:53:06+0000 [HTTPChannelWithXForwardedFor,408,174.52.125.106] [::]   File "/usr/lib/python2.7/site-packages/Django-1.5.1-py2.7.egg/django/db/models/manager.py", line 143, in get
2013-04-06 19:53:06+0000 [HTTPChannelWithXForwardedFor,408,174.52.125.106] [::]     return self.get_query_set().get(*args, **kwargs)
2013-04-06 19:53:06+0000 [HTTPChannelWithXForwardedFor,408,174.52.125.106] [::]   File "/usr/lib/python2.7/site-packages/Django-1.5.1-py2.7.egg/django/db/models/query.py", line 389, in get
2013-04-06 19:53:06+0000 [HTTPChannelWithXForwardedFor,408,174.52.125.106] [::]     (self.model._meta.object_name, kwargs))
2013-04-06 19:53:06+0000 [HTTPChannelWithXForwardedFor,408,174.52.125.106] [::] DoesNotExist: PlayerDB matching query does not exist. Lookup parameters were {'user__id__exact': 1}
2013-04-06 19:53:06+0000 [HTTPChannelWithXForwardedFor,408,174.52.125.106] [EE] No connection User<->Player, maybe database was partially reset?
2013-04-06 19:53:06+0000 [HTTPChannelWithXForwardedFor,408,174.52.125.106] [::] Traceback (most recent call last):
2013-04-06 19:53:06+0000 [HTTPChannelWithXForwardedFor,408,174.52.125.106] [::]   File "/home/YourCyborg/evennia/src/players/manager.py", line 35, in func
2013-04-06 19:53:06+0000 [HTTPChannelWithXForwardedFor,408,174.52.125.106] [::]     players.append(user.get_profile())
2013-04-06 19:53:06+0000 [HTTPChannelWithXForwardedFor,408,174.52.125.106] [::]   File "/usr/lib/python2.7/site-packages/Django-1.5.1-py2.7.egg/django/contrib/auth/models.py", line 450, in get_profile
2013-04-06 19:53:06+0000 [HTTPChannelWithXForwardedFor,408,174.52.125.106] [::]     self._state.db).get(user__id__exact=self.id)
2013-04-06 19:53:06+0000 [HTTPChannelWithXForwardedFor,408,174.52.125.106] [::]   File "/home/YourCyborg/evennia/src/utils/idmapper/manager.py", line 39, in get
2013-04-06 19:53:06+0000 [HTTPChannelWithXForwardedFor,408,174.52.125.106] [::]     inst = super(SharedMemoryManager, self).get(**kwargs)
2013-04-06 19:53:06+0000 [HTTPChannelWithXForwardedFor,408,174.52.125.106] [::]   File "/usr/lib/python2.7/site-packages/Django-1.5.1-py2.7.egg/django/db/models/manager.py", line 143, in get
2013-04-06 19:53:06+0000 [HTTPChannelWithXForwardedFor,408,174.52.125.106] [::]     return self.get_query_set().get(*args, **kwargs)
2013-04-06 19:53:06+0000 [HTTPChannelWithXForwardedFor,408,174.52.125.106] [::]   File "/usr/lib/python2.7/site-packages/Django-1.5.1-py2.7.egg/django/db/models/query.py", line 389, in get
2013-04-06 19:53:06+0000 [HTTPChannelWithXForwardedFor,408,174.52.125.106] [::]     (self.model._meta.object_name, kwargs))
2013-04-06 19:53:06+0000 [HTTPChannelWithXForwardedFor,408,174.52.125.106] [::] DoesNotExist: PlayerDB matching query does not exist. Lookup parameters were {'user__id__exact': 1}
2013-04-06 19:53:06+0000 [HTTPChannelWithXForwardedFor,408,174.52.125.106] [EE] No connection User<->Player, maybe database was partially reset?
2013-04-06 19:54:07+0000 [-] Received SIGINT, shutting down.
2013-04-06 19:54:07+0000 [AMPProtocol,client] AMPProtocol connection lost (HOST:IPv4Address(TCP, '127.0.0.1', 45822) PEER:IPv4Address(TCP, '127.0.0.1', 5000))
2013-04-06 19:54:07+0000 [AMPProtocol,client] <twisted.internet.tcp.Connector instance at 0x2cfb128> will retry in 1 seconds
2013-04-06 19:54:07+0000 [AMPProtocol,client] Stopping factory <src.server.amp.AmpClientFactory instance at 0x2b08c20>
2013-04-06 19:54:07+0000 [-] (TCP Port 8000 Closed)
2013-04-06 19:54:07+0000 [-] Stopping factory <twisted.web.server.Site instance at 0x2c17f38>
2013-04-06 19:54:07+0000 [-] (TCP Port 4000 Closed)
2013-04-06 19:54:07+0000 [-] Stopping factory <twisted.internet.protocol.ServerFactory instance at 0x2c6e368>
2013-04-06 19:54:07+0000 [-] Main loop terminated.
2013-04-06 19:54:07+0000 [-] Server Shut Down.
